<mujoco model="mia_hand_left">
  <compiler angle="radian" meshdir="assets/"/>

  <extension>
    <plugin plugin="mujoco.mia_hand.index_thumb_actuator">
      <instance name="index_thumb_actuator_l">
        <config key="index_flx_jnt_name" value="j_index_fle_l"/>
        <config key="thumb_opp_jnt_name" value="j_thumb_opp_l"/>
        <config key="thumb_opp_start_index_angle" value="-0.06"/>
        <config key="thumb_opp_end_index_angle" value="0.08"/>
      </instance>
    </plugin>
  </extension>

  <default>
    <default class="visual_l">
      <geom type="mesh" contype="0" conaffinity="0" group="0" density="0"/>
    </default>
    <default class="collision_l">
      <geom group="3"/>
    </default>
  </default>

  <asset>
    <mesh name="index_finger_mirrored" content_type="model/obj" file="index_finger_l.obj" scale="0.000999987 0.000999987 0.000999987"/>
    <mesh name="index_tip_mirrored" content_type="model/obj" file="index_tip_l.obj" scale="0.000999987 0.000999987 0.000999987"/>
    <mesh name="little_finger_mirrored" content_type="model/obj" file="little_finger_l.obj" scale="0.000999987 0.000999987 0.000999987"/>
    <mesh name="little_tip_mirrored" content_type="model/obj" file="little_tip_l.obj" scale="0.000999987 0.000999987 0.000999987"/>
    <mesh name="middle_finger_mirrored" content_type="model/obj" file="middle_finger_l.obj" scale="0.000999987 0.000999987 0.000999987"/>
    <mesh name="middle_tip_mirrored" content_type="model/obj" file="middle_tip_l.obj" scale="0.000999987 0.000999987 0.000999987"/>
    <mesh name="dorsum_simple_mirrored" content_type="model/obj" file="dorsum_simple_l.obj" scale="0.0766738 0.104275 0.0766738"/>
    <mesh name="palm_simple_mirrored" content_type="model/obj" file="palm_simple_l.obj" scale="0.122027 0.122027 0.122027"/>
    <mesh name="wrist_mirrored" content_type="model/obj" file="wrist_l.obj" scale="0.000999999 0.000999999 0.001"/>
    <mesh name="ring_finger_mirrored" content_type="model/obj" file="ring_finger_l.obj" scale="0.000999987 0.000999987 0.000999987"/>
    <mesh name="ring_tip_mirrored" content_type="model/obj" file="ring_tip_l.obj" scale="0.000999987 0.000999987 0.000999987"/>
    <mesh name="thumb_cover_mirrored" content_type="model/obj" file="thumb_cover_l.obj" scale="0.000999987 0.000999987 0.000999987"/>
    <mesh name="thumb_frame_mirrored" content_type="model/obj" file="thumb_frame_l.obj" scale="0.000999987 0.000999987 0.000999987"/>
    <mesh name="thumb_metacarpus_mirrored" content_type="model/obj" file="thumb_metacarpus_l.obj" scale="0.000999987 0.000999987 0.000999987"/>
  </asset>

  <worldbody>
    <body name="palm_l" pos="0.1 0 0.2" quat="0.000563312 0.000562864 0.707388 -0.706825">
      <inertial pos="0.00268 -0.0671 -0.016" quat="0.5 0.5 -0.5 0.5" mass="0.274006" diaginertia="0.000343 0.000301 0.00013"/>
      <geom class="visual_l" pos="0.00303524 -0.075372 -0.0252042" quat="0.991445 0.130526 0 0" rgba="0.0156863 0.0156863 0.0156863 1" mesh="dorsum_simple_mirrored"/>
      <geom class="visual_l" pos="0.00380023 -0.0659745 -0.0120549" quat="0.991445 0.130526 0 0" rgba="0.0156863 0.0156863 0.0156863 1" mesh="palm_simple_mirrored"/>
      <geom class="visual_l" pos="-0.04 -0.0152746 -0.0238927" quat="0.793353 -0.608761 0 0" rgba="0.25098 0.25098 0.25098 1" mesh="wrist_mirrored"/>
      <geom class="collision_l" name="collision_hand_distal_l" size="0.0363205 0.0237669 0.0166305" pos="0.000396326 -0.0951293 -0.021127" quat="0.991121 0.130355 0.00905396 -0.0246053" type="box" rgba="0.25098 0.25098 0.25098 1"/>
      <geom class="collision_l" name="collision_hand_proximal_l" size="0.0312073 0.0281913 0.0142893" pos="0.00128842 -0.0462266 -0.00568907" quat="0.986558 0.127037 -0.0954184 -0.0382022" type="box" rgba="0.25098 0.25098 0.25098 1"/>
      <body name="hand_ee_link_l" pos="0 -0.13 0.03" quat="0.947651 0.319309 0 0">
        <inertial pos="0 0 0" mass="0" diaginertia="0 0 0"/>
      </body>
      <body name="thumb_opp_l" pos="0.013074 -0.0681082 -0.00194942" quat="0.749742 -0.617038 0.239056 0.00192414">
        <inertial pos="0.00026099 -0.00762001 0.00121999" quat="0.5 0.5 -0.5 0.5" mass="0.013" diaginertia="1.15e-06 1.12e-06 1.2e-07"/>
        <joint name="j_thumb_opp_l" pos="0 0 0" axis="0 0 -1" range="-0.628 0" actuatorfrcrange="-3.5 3.5" damping="0.2"/>
        <geom class="visual_l" pos="-0.0545238 0.0486952 0.0273073" quat="0.970439 0.0331147 -0.188484 -0.147054" rgba="0.25098 0.25098 0.25098 1" mesh="thumb_metacarpus_mirrored"/>
        <body name="thumb_sensor_l" pos="-5.931e-06 -0.00899765 2.433e-06" quat="1 -9.935e-07 7.44999e-08 6.95001e-08">
          <inertial pos="-1.5e-08 9e-09 -4e-09" quat="0.707107 0.707107 0 0" mass="0.000643" diaginertia="1.5e-08 1.5e-08 8e-09"/>
          <body name="thumb_fle_l" pos="-2.7414e-05 -0.00898978 -1.0546e-05" quat="0.690237 0.153729 -0.690164 -0.15367">
            <inertial pos="0.0127715 -0.0295019 0.000170548" quat="0.500062 0.499938 -0.500114 0.499886" mass="0.0592001" diaginertia="4.1e-05 4e-05 3e-06"/>
            <joint name="j_thumb_fle_l" pos="0 0 0" axis="0 0 -1" range="0 1.1345" actuatorfrcrange="-3.5 3.5" damping="0.1"/>
            <geom class="visual_l" pos="-0.00356782 0.0719755 0.0544858" quat="0.827607 -0.198854 0.522145 0.0537452" rgba="1 1 1 1" mesh="thumb_cover_mirrored"/>
            <geom class="visual_l" pos="-0.00356782 0.0719755 0.0544858" quat="0.827607 -0.198854 0.522145 0.0537452" rgba="0.25098 0.25098 0.25098 1" mesh="thumb_frame_mirrored"/>
            <geom class="collision_l" name="collision_thumb_distal_l" size="0.0116941 0.0275092" pos="0.0156689 -0.0473847 0.0014039" quat="0.736368 -0.669124 0.0564767 0.0827358" type="cylinder" rgba="0.25098 0.25098 0.25098 1"/>
            <geom class="collision_l" name="collision_thumb_proximal_l" size="0.0127144 0.0299093" pos="0.0156133 -0.0326076 6.2183e-05" quat="0.707582 -0.695412 0.0575247 0.111445" type="cylinder" rgba="0.25098 0.25098 0.25098 1"/>
            <geom class="collision_l" name="collision_thumb_tip_l" size="0.0105148" pos="0.0157022 -0.069964 -0.000759777" quat="0.873883 0.262638 0.209606 -0.351306" rgba="0.25098 0.25098 0.25098 1"/>
          </body>
        </body>
      </body>
      <body name="index_fle_l" pos="0.0263055 -0.110217 -0.0215208" quat="0.745782 -0.0196446 0.660056 0.0880324">
        <inertial pos="-0.000420164 -0.00730602 0.000122763" quat="0.707107 0.707107 0 0" mass="0.0113" diaginertia="8.39e-07 8.39e-07 8.39e-07"/>
        <joint name="j_index_fle_l" pos="0 0 0" axis="0 0 -1" range="-1.4 1.4" actuatorfrcrange="-1.75 1.75" damping="0.1"/>
        <geom class="collision_l" name="collision_index_pre_sensor_l" size="0.0071285 0.00848527" pos="0.000159711 -0.023607 0.00150841" quat="0.513726 -0.530536 -0.469438 -0.483989" type="cylinder"/>
        <body name="index_sensor_l" pos="-0.000399264 -0.024237 -0.00018397" quat="0.996301 -0.000323171 -7.70693e-05 -0.0859352">
          <inertial pos="0 0 0" quat="0.554664 0.449921 -0.545354 0.438757" mass="0.01765" diaginertia="2.19001e-05 2.16199e-05 7.8994e-07"/>
          <geom class="visual_l" pos="-0.016737 0.126896 -0.0512699" quat="0.642105 -0.396242 -0.505804 -0.418157" rgba="0.0156863 0.0156863 0.0156863 1" mesh="index_finger_mirrored"/>
          <geom class="visual_l" pos="-0.016737 0.126896 -0.0512699" quat="0.642105 -0.396242 -0.505804 -0.418157" rgba="1 1 1 1" mesh="index_tip_mirrored"/>
          <geom class="collision_l" name="collision_index_distal_l" size="0.00795738 0.0151856" pos="-0.00189978 -0.0412638 0.00138145" quat="0.415019 -0.601436 -0.383289 -0.56491" type="cylinder" rgba="1 1 1 1"/>
          <geom class="collision_l" name="collision_index_post_sensor_l" size="0.0071285 0.00713106" pos="0.00270224 -0.0145998 0.00127784" quat="0.555422 -0.47484 -0.515383 -0.447676" type="cylinder" rgba="1 1 1 1"/>
          <geom class="collision_l" name="collision_index_tip_l" size="0.00662717" pos="-0.0104493 -0.0596592 0.000670582" quat="0.735087 -0.0767551 -0.646393 -0.189557" rgba="1 1 1 1"/>
        </body>
      </body>
      <body name="middle_fle_l" pos="0.00514942 -0.113555 -0.0243453" quat="0.706434 0.0308436 0.706434 0.0308435">
        <inertial pos="0 0 0" quat="0.707093 0.707107 0.00306118 0.00307185" mass="0.0121" diaginertia="1.42009e-06 1.3e-06 1.97908e-07"/>
        <joint name="j_mrl_fle_l" pos="0 0 0" axis="0 0 -1" range="0 1.39626" actuatorfrcrange="-1.75 1.75" damping="0.1"/>
        <geom class="collision_l" name="collision_middle_pre_sensor_l" size="0.00683449 0.00891176" pos="5.4868e-05 -0.0200986 0.000735957" quat="0.499613 -0.500386 -0.499613 -0.500386" type="cylinder"/>
        <body name="middle_sensor_l" pos="0.000444012 -0.0254975 5.81e-07" quat="1 -9e-09 1.035e-07 7.5e-09">
          <inertial pos="0 0 0" quat="0.547188 0.439409 -0.552842 0.4493" mass="0.0177" diaginertia="2.19002e-05 2.162e-05 7.89803e-07"/>
          <geom class="visual_l" pos="0.00767081 0.123443 -0.04515" quat="0.541675 -0.454519 -0.541675 -0.454519" rgba="0.0156863 0.0156863 0.0156863 1" mesh="middle_finger_mirrored"/>
          <geom class="visual_l" pos="0.00767081 0.123443 -0.04515" quat="0.541675 -0.454519 -0.541675 -0.454519" rgba="1 1 1 1" mesh="middle_tip_mirrored"/>
          <geom class="collision_l" name="collision_middle_distal_l" size="0.00812763 0.0191194" pos="-0.00865379 -0.0394251 0.00073538" quat="0.354525 -0.611811 -0.354525 -0.611811" type="cylinder" rgba="1 1 1 1"/>
          <geom class="collision_l" name="collision_middle_post_sensor_l" size="0.00683449 0.00591472" pos="-0.000414368 -0.0109209 0.00073538" quat="0.499613 -0.500386 -0.499613 -0.500386" type="cylinder" rgba="1 1 1 1"/>
          <geom class="collision_l" name="collision_middle_tip_l" size="0.00562753" pos="-0.0205398 -0.0564038 0.00073538" quat="0.682871 -0.183541 -0.682871 -0.183541" rgba="1 1 1 1"/>
        </body>
      </body>
      <body name="ring_fle_l" pos="-0.0122504 -0.112029 -0.0239364" quat="0.690637 0.0971483 0.716264 -0.0234157">
        <inertial pos="-0.00112 -0.0264 0.000203993" quat="0.5 0.5 -0.5 0.5" mass="0.0263" diaginertia="1.61e-05 1.577e-05 9.02e-07"/>
        <joint name="j_ring_fle_l" pos="0 0 0" axis="0 0 -1" range="0 1.39626" actuatorfrcrange="-1.75 1.75" damping="0.1"/>
        <geom class="visual_l" pos="0.0110461 0.090067 -0.0435588" quat="-0.488779 0.497506 0.582505 0.417457" rgba="0.0156863 0.0156863 0.0156863 1" mesh="ring_finger_mirrored"/>
        <geom class="visual_l" pos="0.0110461 0.090067 -0.0435588" quat="-0.488779 0.497506 0.582505 0.417457" rgba="1 1 1 1" mesh="ring_tip_mirrored"/>
        <geom class="collision_l" name="collision_ring_distal_l" size="0.00760354 0.0149668" pos="-0.00852139 -0.0632753 0.000219084" quat="-0.344487 0.614585 0.347078 0.618992" type="cylinder" rgba="1 1 1 1"/>
        <geom class="collision_l" name="collision_ring_proximal_l" size="0.00782782 0.0184141" pos="0.00118692 -0.0289251 0.000219103" quat="0.5 -0.5 -0.5 -0.5" type="cylinder" rgba="1 1 1 1"/>
        <geom class="collision_l" name="collision_ring_tip_l" size="0.00487311" pos="-0.0182312 -0.0766421 -0.000189719" quat="0.664463 -0.241845 -0.696364 -0.122788" rgba="1 1 1 1"/>
      </body>
      <body name="little_fle_l" pos="-0.02786 -0.107325 -0.0206051" quat="0.684193 0.193957 0.701244 -0.0501746">
        <inertial pos="-0.00155 -0.0208 -3.5805e-05" quat="0.5 0.5 -0.5 0.5" mass="0.0207" diaginertia="7.9e-06 7.686e-06 6.52e-07"/>
        <joint name="j_little_fle_l" pos="0 0 0" axis="0 0 -1" range="0 1.39626" actuatorfrcrange="-1.75 1.75" damping="0.1"/>
        <geom class="visual_l" pos="0.021799 0.0798844 -0.0421284" quat="0.424734 -0.570387 -0.586878 -0.387084" rgba="0.0156863 0.0156863 0.0156863 1" mesh="little_finger_mirrored"/>
        <geom class="visual_l" pos="0.021799 0.0798844 -0.0421284" quat="0.424734 -0.570387 -0.586878 -0.387084" rgba="1 1 1 1" mesh="little_tip_mirrored"/>
        <geom class="collision_l" name="collision_little_distal_l" size="0.00760354 0.0149668" pos="-0.00907162 -0.0523633 0.000405852" quat="0.378417 -0.606914 -0.369575 -0.593186" type="cylinder" rgba="1 1 1 1"/>
        <geom class="collision_l" name="collision_little_proximal_l" size="0.00782783 0.015221" pos="-0.00197874 -0.0273017 -4.4681e-05" quat="0.492576 -0.522025 -0.478044 -0.506292" type="cylinder" rgba="1 1 1 1"/>
        <geom class="collision_l" name="collision_little_tip_l" size="0.00484472" pos="-0.0165956 -0.064732 -0.000363795" quat="0.653774 -0.266396 -0.707705 -0.0276879" rgba="1 1 1 1"/>
      </body>
    </body>
  </worldbody>

  <equality>
    <joint joint1="j_ring_fle_l"   joint2="j_mrl_fle_l"/>
    <joint joint1="j_little_fle_l" joint2="j_mrl_fle_l"/>
  </equality>

  <contact>
    <exclude body1="palm_l" body2="thumb_fle_l"/>
    <exclude body1="palm_l" body2="thumb_opp_l"/>
    <exclude body1="palm_l" body2="index_fle_l"/>
    <exclude body1="palm_l" body2="middle_fle_l"/>
    <exclude body1="palm_l" body2="ring_fle_l"/>
    <exclude body1="palm_l" body2="little_fle_l"/>
  </contact>

  <actuator>
    <position name="thumb_fle_pos_l" joint="j_thumb_fle_l" inheritrange="1"/>
    <plugin name="index_fle_pos_l" joint="j_index_fle_l" plugin="mujoco.mia_hand.index_thumb_actuator" instance="index_thumb_actuator_l"/>
    <position name="mrl_fle_pos_l" joint="j_mrl_fle_l" inheritrange="1"/>
  </actuator>
</mujoco>
